<?xml version="1.0" ?>
<!-- =================================================================================== -->
<!-- |    This document was autogenerated by xacro from robot.xacro                    | -->
<!-- |    EDITING THIS FILE BY HAND IS NOT RECOMMENDED                                 | -->
<!-- =================================================================================== -->
<robot name="h1">
  <!--   <xacro:include filename="$(find h1_description)/xacro/transmission.xacro"/>   -->
  <material name="black">
    <color rgba="0.0 0.0 0.0 1.0"/>
  </material>
  <material name="blue">
    <color rgba="0.15 0.31 0.45 1.0"/>
  </material>
  <material name="green">
    <color rgba="0.0 0.8 0.0 1.0"/>
  </material>
  <material name="grey">
    <color rgba="0.2 0.2 0.2 1.0"/>
  </material>
  <material name="silver">
    <color rgba="0.9137254901960784 0.9137254901960784 0.8470588235294118 1.0"/>
  </material>
  <material name="orange">
    <color rgba="1.0 0.4235294117647059 0.0392156862745098 1.0"/>
  </material>
  <material name="brown">
    <color rgba="0.96 0.87 0.81 1.0"/>
  </material>
  <material name="red">
    <color rgba="0.8 0.0 0.0 1.0"/>
  </material>
  <material name="white">
    <color rgba="1.0 1.0 1.0 1.0"/>
  </material>
  <gazebo>
    <plugin filename="libhunter_bipedal_hw_sim.so" name="gazebo_ros_control">
      <robotNamespace>/</robotNamespace>
      <robotParam>legged_robot_description</robotParam>
      <robotSimType>legged_gazebo/LeggedHWSim</robotSimType>
    </plugin>
  </gazebo>
  <gazebo>
    <plugin filename="libgazebo_ros_p3d.so" name="p3d_base_controller">
      <alwaysOn>true</alwaysOn>
      <updateRate>500.0</updateRate>
      <bodyName>base_link</bodyName>
      <topicName>ground_truth/state</topicName>
      <gaussianNoise>0</gaussianNoise>
      <frameName>world</frameName>
      <xyzOffsets>0 0 0</xyzOffsets>
      <rpyOffsets>0 0 0</rpyOffsets>
    </plugin>
  </gazebo>
  <!--    禁用对固定关节的联合优化-->
  <gazebo reference="imu_joint">
    <disableFixedJointLumping>true</disableFixedJointLumping>
  </gazebo>
  <gazebo reference="leg_l1_link">
    <mu1>0.6</mu1>
    <mu2>0.6</mu2>
    <self_collide>1</self_collide>
  </gazebo>
  <gazebo reference="leg_l2_link">
    <mu1>0.6</mu1>
    <mu2>0.6</mu2>
    <self_collide>1</self_collide>
  </gazebo>
  <gazebo reference="leg_l3_link">
    <mu1>0.6</mu1>
    <mu2>0.6</mu2>
    <self_collide>1</self_collide>
  </gazebo>
  <gazebo reference="leg_l4_link">
    <mu1>0.6</mu1>
    <mu2>0.6</mu2>
    <self_collide>1</self_collide>
  </gazebo>
  <gazebo reference="leg_l5_link">
    <mu1>1.5</mu1>
    <mu2>1.5</mu2>
    <self_collide>1</self_collide>
    <kp value="1000000.0"/>
    <kd value="100.0"/>
    <maxVel>1.0</maxVel>
    <minDepth>0.00</minDepth>
  </gazebo>
  <gazebo reference="leg_l_f1_link">
    <mu1>1.5</mu1>
    <mu2>1.5</mu2>
    <self_collide>1</self_collide>
    <kp value="1000000.0"/>
    <kd value="100.0"/>
    <maxVel>1.0</maxVel>
    <minDepth>0.00</minDepth>
  </gazebo>
  <gazebo reference="leg_l_f2_link">
    <mu1>1.5</mu1>
    <mu2>1.5</mu2>
    <self_collide>1</self_collide>
    <kp value="1000000.0"/>
    <kd value="100.0"/>
    <maxVel>1.0</maxVel>
    <minDepth>0.00</minDepth>
  </gazebo>
  <gazebo reference="leg_r1_link">
    <mu1>0.6</mu1>
    <mu2>0.6</mu2>
    <self_collide>1</self_collide>
  </gazebo>
  <gazebo reference="leg_r2_link">
    <mu1>0.6</mu1>
    <mu2>0.6</mu2>
    <self_collide>1</self_collide>
  </gazebo>
  <gazebo reference="leg_r3_link">
    <mu1>0.6</mu1>
    <mu2>0.6</mu2>
    <self_collide>1</self_collide>
  </gazebo>
  <gazebo reference="leg_r4_link">
    <mu1>0.6</mu1>
    <mu2>0.6</mu2>
    <self_collide>1</self_collide>
  </gazebo>
  <gazebo reference="leg_r5_link">
    <mu1>1.5</mu1>
    <mu2>1.5</mu2>
    <self_collide>1</self_collide>
    <kp value="1000000.0"/>
    <kd value="100.0"/>
    <maxVel>1.0</maxVel>
    <minDepth>0.00</minDepth>
  </gazebo>
  <gazebo reference="leg_r_f1_link">
    <mu1>1.5</mu1>
    <mu2>1.5</mu2>
    <self_collide>1</self_collide>
    <kp value="1000000.0"/>
    <kd value="100.0"/>
    <maxVel>1.0</maxVel>
    <minDepth>0.00</minDepth>
  </gazebo>
  <gazebo reference="leg_r_f2_link">
    <mu1>1.5</mu1>
    <mu2>1.5</mu2>
    <self_collide>1</self_collide>
    <kp value="1000000.0"/>
    <kd value="100.0"/>
    <maxVel>1.0</maxVel>
    <minDepth>0.00</minDepth>
  </gazebo>
  <link name="base_link">
    <visual>
      <origin rpy="0 0 0" xyz="0 0 0"/>
      <geometry>
        <mesh filename="package://h1_description/meshes/stl/base_link.STL" scale="1 1 1"/>
      </geometry>
      <material name="blue"/>
    </visual>
    <collision>
      <origin rpy="0 0 0" xyz="0 0 0.033833333333333326"/>
      <geometry>
        <box size="0.15866666666666665 0.26 0.3353333333333333"/>
      </geometry>
    </collision>
    <inertial>
      <origin rpy="0 0 0" xyz="-0.029148 -8.6e-05 0.009226"/>
      <mass value="14.0"/>
      <inertia ixx="0.487006" ixy="-3.4e-05" ixz="0.044679" iyy="0.427603" iyz="-3.7e-05" izz="0.219108"/>
    </inertial>
  </link>
  <joint name="imu_joint" type="fixed">
    <origin rpy="0. 0. 0." xyz="0. 0. 0"/>
    <parent link="base_link"/>
    <child link="imu_link"/>
  </joint>
  <!-- Imu link -->
  <link name="imu_link">
    <inertial>
      <mass value="0.01"/>
      <origin rpy="0 0 0" xyz="0 0 0"/>
      <inertia ixx="0.000001" ixy="0" ixz="0" iyy="0.000001" iyz="0" izz="0.000001"/>
    </inertial>
    <visual>
      <origin rpy="0 0 0" xyz="0 0 0"/>
      <geometry>
        <box size="0.015 0.015 0.004"/>
      </geometry>
    </visual>
    <material name="orange">
      <color rgba="255 108 10 255"/>
    </material>
  </link>
  <joint name="arm_r1_joint" type="fixed">
    <origin rpy="0 0 0" xyz="0.02 -0.255 0.170"/>
    <parent link="base_link"/>
    <child link="arm_r1_link"/>
    <axis xyz="0 1 0"/>
    <dynamics damping="0" friction="0"/>
    <limit effort="24" lower="-3.141592653589793" upper="1.5707963267948966" velocity="40"/>
  </joint>
  <link name="arm_r1_link">
    <visual>
      <origin rpy="0 0 0" xyz="0 0 0"/>
      <geometry>
        <mesh filename="package://h1_description/meshes/stl/arm_r1_link.STL" scale="1 1 1"/>
      </geometry>
      <material name="brown"/>
    </visual>
    <collision>
      <origin rpy="0 1.5707963267948966 0" xyz="0 0 0"/>
      <geometry>
        <cylinder length="0.04" radius="0.0405"/>
      </geometry>
    </collision>
    <inertial>
      <origin rpy="0 0 0" xyz="0.000675 0.002958 0.00012"/>
      <mass value="0.622855"/>
      <inertia ixx="0.000655" ixy="7e-06" ixz="1e-06" iyy="0.000378" iyz="0.0" izz="0.000431"/>
    </inertial>
  </link>
  <joint name="arm_r2_joint" type="fixed">
    <origin rpy="0 0 0" xyz="0 0 0"/>
    <parent link="arm_r1_link"/>
    <child link="arm_r2_link"/>
    <axis xyz="1 0 0"/>
    <dynamics damping="0" friction="0"/>
    <limit effort="24" lower="-2.897246558310587" upper="0.0" velocity="40"/>
  </joint>
  <link name="arm_r2_link">
    <visual>
      <origin rpy="0 0 0" xyz="0 0 0"/>
      <geometry>
        <mesh filename="package://h1_description/meshes/stl/arm_r2_link.STL" scale="1 1 1"/>
      </geometry>
      <material name="brown"/>
    </visual>
    <collision>
      <origin rpy="0 1.5707963267948966 0" xyz="0 0 -0.155"/>
      <geometry>
        <box size="0.22 0.0472 0.032"/>
      </geometry>
    </collision>
    <inertial>
      <origin rpy="0 0 0" xyz="0.007666 -0.000655 -0.187497"/>
      <mass value="0.686346"/>
      <inertia ixx="0.009735" ixy="-6e-06" ixz="-0.000765" iyy="0.009958" iyz="5e-05" izz="0.00046"/>
    </inertial>
  </link>
  <joint name="arm_r3_joint" type="fixed">
    <!--    <origin rpy="0 0 0" xyz="0 0 ${-arm_r2_link_length}"/>   -->
    <!--   <origin rpy="0 0 0" xyz="0.04 -0.007 -0.2958"/>   -->
    <origin rpy="0 0 0" xyz="0.022 -0.007 -0.30"/>
    <parent link="arm_r2_link"/>
    <child link="arm_r3_link"/>
    <axis xyz="0 1 0"/>
    <dynamics damping="0" friction="0"/>
    <limit effort="12" lower="-2.8797932657906435" upper="0.6981317007977318" velocity="30"/>
  </joint>
  <link name="arm_r3_link">
    <visual>
      <origin rpy="0 0 0" xyz="0 0 0"/>
      <geometry>
        <mesh filename="package://h1_description/meshes/stl/arm_r3_link.STL" scale="1 1 1"/>
      </geometry>
      <material name="brown"/>
    </visual>
    <collision>
      <origin rpy="0 1.5707963267948966 0" xyz="0 0 -0.15"/>
      <geometry>
        <box size="0.24 0.042 0.054"/>
      </geometry>
    </collision>
    <inertial>
      <origin rpy="0 0 0" xyz="0.070594 0.0473114 -0.064586"/>
      <mass value="0.490185"/>
      <inertia ixx="0.005139" ixy="0.001322" ixz="1.5e-05" iyy="0.000674" iyz="4.9e-05" izz="0.005476"/>
    </inertial>
  </link>
  <joint name="arm_l1_joint" type="fixed">
    <origin rpy="0 0 0" xyz="0.02 0.255 0.170"/>
    <parent link="base_link"/>
    <child link="arm_l1_link"/>
    <axis xyz="0 1 0"/>
    <dynamics damping="0" friction="0"/>
    <limit effort="24" lower="-3.141592653589793" upper="1.5707963267948966" velocity="40"/>
  </joint>
  <link name="arm_l1_link">
    <visual>
      <origin rpy="0 0 0" xyz="0 0 0"/>
      <geometry>
        <mesh filename="package://h1_description/meshes/stl/arm_l1_link.STL" scale="1 1 1"/>
      </geometry>
      <material name="brown"/>
    </visual>
    <collision>
      <!--   <origin rpy="${pi/2.0} 0 0" xyz="0 0 0"/>   -->
      <origin rpy="0 1.5707963267948966 0" xyz="0 0 0"/>
      <geometry>
        <cylinder length="0.04" radius="0.0405"/>
      </geometry>
    </collision>
    <inertial>
      <origin rpy="0 0 0" xyz="-0.000475 -0.002959 3e-05"/>
      <mass value="0.622855"/>
      <inertia ixx="0.000655" ixy="-7e-06" ixz="1e-06" iyy="0.000379" iyz="2e-06" izz="0.000431"/>
    </inertial>
  </link>
  <joint name="arm_l2_joint" type="fixed">
    <origin rpy="0 0 0" xyz="0 0 0"/>
    <parent link="arm_l1_link"/>
    <child link="arm_l2_link"/>
    <axis xyz="1 0 0"/>
    <dynamics damping="0" friction="0"/>
    <limit effort="24" lower="0.0" upper="2.897246558310587" velocity="40"/>
  </joint>
  <link name="arm_l2_link">
    <visual>
      <origin rpy="0 0 0" xyz="0 0 0"/>
      <geometry>
        <mesh filename="package://h1_description/meshes/stl/arm_l2_link.STL" scale="1 1 1"/>
      </geometry>
      <material name="brown"/>
    </visual>
    <collision>
      <origin rpy="0 1.5707963267948966 0" xyz="0 0 -0.155"/>
      <geometry>
        <box size="0.22 0.0472 0.032"/>
      </geometry>
    </collision>
    <inertial>
      <origin rpy="0 0 0" xyz="-0.012334 -0.000655 0.111803"/>
      <mass value="0.686346"/>
      <inertia ixx="0.009735" ixy="-6e-06" ixz="-0.000765" iyy="0.009958" iyz="5e-05" izz="0.00046"/>
    </inertial>
  </link>
  <joint name="arm_l3_joint" type="fixed">
    <!--   <origin rpy="0 0 0" xyz="0 0 ${-arm_l2_link_length}"/>    -->
    <!--    <origin rpy="0 0 0" xyz="0.04 -0.007 -0.2958"/>  -->
    <origin rpy="0 0 0" xyz="0.022 -0.007 -0.30"/>
    <parent link="arm_l2_link"/>
    <child link="arm_l3_link"/>
    <axis xyz="0 1 0"/>
    <dynamics damping="0" friction="0"/>
    <limit effort="12" lower="-2.8797932657906435" upper="0.6981317007977318" velocity="30"/>
  </joint>
  <link name="arm_l3_link">
    <visual>
      <origin rpy="0 0 0" xyz="0 0 0"/>
      <geometry>
        <mesh filename="package://h1_description/meshes/stl/arm_l3_link.STL" scale="1 1 1"/>
      </geometry>
      <material name="brown"/>
    </visual>
    <collision>
      <origin rpy="0 1.5707963267948966 0" xyz="0 0 -0.15"/>
      <geometry>
        <box size="0.24 0.042 0.054"/>
      </geometry>
    </collision>
    <inertial>
      <origin rpy="0 0 0" xyz="-0.018007 0.000613 -0.177358"/>
      <mass value="0.490185"/>
      <inertia ixx="0.005496" ixy="2e-06" ixz="0.000169" iyy="0.005477" iyz="4.5e-05" izz="0.000317"/>
    </inertial>
  </link>
  <joint name="leg_r1_joint" type="revolute">
    <!--      <origin rpy="0 ${-pi/4.0} 0" xyz="-0.104 -0.081 -0.281"-0.02 0.080 -0.202/>  -->
    <origin rpy="0 0 0" xyz="0.02 -0.080 -0.202"/>
    <parent link="base_link"/>
    <child link="leg_r1_link"/>
    <axis xyz="1 0 0"/>
    <dynamics damping="0" friction="0"/>
    <limit effort="144" lower="-0.4886921905584123" upper="0.20943951023931953" velocity="45"/>
  </joint>
  <link name="leg_r1_link">
    <visual>
      <origin rpy="0 0 0" xyz="0 0 0"/>
      <geometry>
        <mesh filename="package://h1_description/meshes/stl/leg_r1_link.STL" scale="1 1 1"/>
      </geometry>
      <material name="brown"/>
    </visual>
    <collision>
      <origin rpy="0 0 0" xyz="0 0 0"/>
      <geometry>
        <cylinder length="0.05" radius="0.0558"/>
      </geometry>
    </collision>
    <inertial>
      <origin rpy="0 0 0" xyz="-0.004667 0.000931 -0.005738"/>
      <mass value="1.682739"/>
      <inertia ixx="0.001819" ixy="1.7e-05" ixz="-6.6e-05" iyy="0.002122" iyz="-1.6e-05" izz="0.002855"/>
    </inertial>
  </link>
  <joint name="leg_r2_joint" type="revolute">
    <!--      <origin rpy="0 0 0" xyz="0.148 -0.005 -0.01"/>   -->
    <origin rpy="0 0 0" xyz="0 -0.006 -0.13"/>
    <parent link="leg_r1_link"/>
    <child link="leg_r2_link"/>
    <axis xyz="0 0 1"/>
    <dynamics damping="0" friction="0"/>
    <limit effort="144" lower="-0.5235987755982988" upper="0.20943951023931953" velocity="45"/>
  </joint>
  <link name="leg_r2_link">
    <visual>
      <origin rpy="0 0 0" xyz="0 0 0"/>
      <geometry>
        <mesh filename="package://h1_description/meshes/stl/leg_r2_link.STL" scale="1 1 1"/>
      </geometry>
      <material name="brown"/>
    </visual>
    <collision>
      <origin rpy="1.5707963267948966 0 0" xyz="0.01 0 0"/>
      <geometry>
        <cylinder length="0.052" radius="0.087"/>
      </geometry>
    </collision>
    <inertial>
      <origin rpy="0 0 0" xyz="-0.001279 2e-05 0.007954"/>
      <mass value="2.697319"/>
      <inertia ixx="0.0073" ixy="-4e-06" ixz="0.000181" iyy="0.0125" iyz="-8.2e-05" izz="0.006774"/>
    </inertial>
  </link>
  <joint name="leg_r3_joint" type="revolute">
    <!--     <origin rpy="0 0 0" xyz="0 -0.057 0"/>   -->
    <origin rpy="0 0 0" xyz="0 -0.057 0"/>
    <parent link="leg_r2_link"/>
    <child link="leg_r3_link"/>
    <axis xyz="0 -1 0"/>
    <dynamics damping="0" friction="0"/>
    <limit effort="200" lower="-1.1344640137963142" upper="1.335176877775662" velocity="45"/>
  </joint>
  <link name="leg_r3_link">
    <visual>
      <origin rpy="0 0 0" xyz="0 0 0"/>
      <geometry>
        <mesh filename="package://h1_description/meshes/stl/leg_r3_link.STL" scale="1 1 1"/>
      </geometry>
      <material name="brown"/>
    </visual>
    <collision>
      <origin rpy="0 1.5707963267948966 0" xyz="0.03 0 -0.200"/>
      <geometry>
        <box size="0.3 0.05 0.05"/>
      </geometry>
    </collision>
    <inertial>
      <origin rpy="0 0 0" xyz="0.010801 -0.015919 -0.088156"/>
      <mass value="6.133134"/>
      <inertia ixx="0.123582" ixy="0.001076" ixz="-0.007036" iyy="0.126866" iyz="-0.008649" izz="0.011662"/>
    </inertial>
  </link>
  <joint name="leg_r4_joint" type="revolute">
    <!--   <origin rpy="0 0 0" xyz="0 0 -0.400"/>  -->
    <origin rpy="0 0 0" xyz="0 0 -0.400"/>
    <parent link="leg_r3_link"/>
    <child link="leg_r4_link"/>
    <axis xyz="0 -1 0"/>
    <dynamics damping="0" friction="0"/>
    <limit effort="200" lower="-2.4958208303518914" upper="-0.0" velocity="45"/>
  </joint>
  <link name="leg_r4_link">
    <visual>
      <origin rpy="0 0 0" xyz="0 0 0"/>
      <geometry>
        <mesh filename="package://h1_description/meshes/stl/leg_r4_link.STL" scale="1 1 1"/>
      </geometry>
      <material name="brown"/>
    </visual>
    <collision>
      <origin rpy="0 1.5707963267948966 0" xyz="0 0 -0.20"/>
      <geometry>
        <box size="0.45 0.05 0.05"/>
      </geometry>
    </collision>
    <inertial>
      <origin rpy="0 0 0" xyz="0.01358 -0.005401 -0.18676"/>
      <mass value="2.757724"/>
      <inertia ixx="0.052429" ixy="0.000618" ixz="0.002695" iyy="0.053962" iyz="0.002004" izz="0.003135"/>
    </inertial>
  </link>
  <joint name="leg_r5_joint" type="revolute">
    <origin rpy="0 0 0" xyz="0 0 -0.4"/>
    <parent link="leg_r4_link"/>
    <child link="leg_r5_link"/>
    <axis xyz="0 1 0"/>
    <dynamics damping="0" friction="0"/>
    <limit effort="48" lower="-1.4835298641951802" upper="1.2042771838760873" velocity="40"/>
  </joint>
  <link name="leg_r5_link">
    <visual>
      <!--    <origin rpy="0 0 0" xyz="${rightfoot_length/2.0} 0 0"/>  -->
      <origin rpy="0 0 0" xyz="0 0 0"/>
      <geometry>
        <mesh filename="package://h1_description/meshes/stl/leg_r5_link.STL" scale="1 1 1"/>
      </geometry>
      <material name="brown"/>
    </visual>
    <collision>
      <origin rpy="0 0 0" xyz="0.05 0 -0.04"/>
      <geometry>
        <box size="0.2 0.053 0.01"/>
      </geometry>
    </collision>
    <inertial>
      <origin rpy="0 0 0" xyz="0.033343 0.0 -0.028227"/>
      <mass value="0.325911"/>
      <inertia ixx="0.000104" ixy="0.0" ixz="-0.000115" iyy="0.001122" iyz="0.0" izz="0.001104"/>
    </inertial>
  </link>
  <joint name="leg_r5_fixed_1" type="fixed">
    <origin rpy="0 0 0" xyz="0.12 0 -0.04"/>
    <parent link="leg_r5_link"/>
    <child link="leg_r_f1_link"/>
  </joint>
  <link name="leg_r_f1_link">
    <inertial>
      <mass value="0.01"/>
      <inertia ixx="0.000001" ixy="0" ixz="0" iyy="0.000001" iyz="0" izz="0.000001"/>
    </inertial>
    <visual>
      <origin rpy="0 0 0" xyz="0 0 0"/>
      <geometry>
        <sphere radius="0.001"/>
      </geometry>
    </visual>
    <collision>
      <origin rpy="0 0 0" xyz="0 0 0"/>
      <geometry>
        <sphere radius="0.001"/>
      </geometry>
    </collision>
  </link>
  <joint name="leg_r5_fixed_2" type="fixed">
    <origin rpy="0 0 0" xyz="-0.01 0 -0.04"/>
    <parent link="leg_r5_link"/>
    <child link="leg_r_f2_link"/>
  </joint>
  <link name="leg_r_f2_link">
    <inertial>
      <mass value="0.01"/>
      <inertia ixx="0.000001" ixy="0" ixz="0" iyy="0.000001" iyz="0" izz="0.000001"/>
    </inertial>
    <visual>
      <origin rpy="0 0 0" xyz="0 0 0"/>
      <geometry>
        <sphere radius="0.001"/>
      </geometry>
    </visual>
    <collision>
      <origin rpy="0 0 0" xyz="0 0 0"/>
      <geometry>
        <sphere radius="0.001"/>
      </geometry>
    </collision>
  </link>
  <joint name="leg_l1_joint" type="revolute">
    <origin rpy="0 0 0" xyz="0.02 0.080 -0.202"/>
    <parent link="base_link"/>
    <child link="leg_l1_link"/>
    <axis xyz="1 0 0"/>
    <dynamics damping="0" friction="0"/>
    <limit effort="144" lower="-0.20943951023931953" upper="0.4886921905584123" velocity="45"/>
  </joint>
  <link name="leg_l1_link">
    <visual>
      <origin rpy="0 0 0" xyz="0 0 0"/>
      <geometry>
        <mesh filename="package://h1_description/meshes/stl/leg_l1_link.STL" scale="1 1 1"/>
      </geometry>
      <material name="brown"/>
    </visual>
    <collision>
      <origin rpy="0 0 0" xyz="0 0 0"/>
      <geometry>
        <cylinder length="0.05" radius="0.0558"/>
      </geometry>
    </collision>
    <inertial>
      <origin rpy="0 0 0" xyz="-0.004667 0.000931 -0.005738"/>
      <mass value="1.682739"/>
      <inertia ixx="0.001819" ixy="1.7e-05" ixz="-6.6e-05" iyy="0.002122" iyz="-1.6e-05" izz="0.002855"/>
    </inertial>
  </link>
  <joint name="leg_l2_joint" type="revolute">
    <!--   <origin rpy="0 0 0" xyz="0.103 0 -0.103"/>0 -0.006 -0.13  -->
    <origin rpy="0 0 0" xyz="0 -0.006 -0.13"/>
    <parent link="leg_l1_link"/>
    <child link="leg_l2_link"/>
    <axis xyz="0 0 1"/>
    <dynamics damping="0" friction="0"/>
    <limit effort="144" lower="-0.20943951023931953" upper="0.5235987755982988" velocity="45"/>
  </joint>
  <link name="leg_l2_link">
    <visual>
      <origin rpy="0 0 0" xyz="0 0 0"/>
      <geometry>
        <mesh filename="package://h1_description/meshes/stl/leg_l2_link.STL" scale="1 1 1"/>
      </geometry>
      <material name="brown"/>
    </visual>
    <collision>
      <!-- <origin rpy="${pi/2} 0 0" xyz="${leg_l2_link_radius} 0 0"/>       -->
      <origin rpy="1.5707963267948966 0 0" xyz="0 0 0"/>
      <geometry>
        <cylinder length="0.052" radius="0.087"/>
      </geometry>
    </collision>
    <inertial>
      <origin rpy="0 0 0" xyz="-0.001279 -2e-05 0.007954"/>
      <mass value="2.697319"/>
      <inertia ixx="0.0073" ixy="4e-06" ixz="0.000181" iyy="0.0125" iyz="8.2e-05" izz="0.006774"/>
    </inertial>
  </link>
  <joint name="leg_l3_joint" type="revolute">
    <!--   <origin rpy="0 0 0" xyz="0 0.057 0"/> -->
    <origin rpy="0 0 0" xyz="0 0.057 0"/>
    <parent link="leg_l2_link"/>
    <child link="leg_l3_link"/>
    <axis xyz="0 -1 0"/>
    <dynamics damping="0" friction="0"/>
    <limit effort="200" lower="-1.1344640137963142" upper="1.335176877775662" velocity="45"/>
  </joint>
  <link name="leg_l3_link">
    <visual>
      <origin rpy="0 0 0" xyz="0 0 0"/>
      <geometry>
        <mesh filename="package://h1_description/meshes/stl/leg_l3_link.STL" scale="1 1 1"/>
      </geometry>
      <material name="brown"/>
    </visual>
    <collision>
      <origin rpy="0 1.5707963267948966 0" xyz="0.03 0 -0.200"/>
      <geometry>
        <box size="0.3 0.05 0.05"/>
      </geometry>
    </collision>
    <inertial>
      <origin rpy="0 0 0" xyz="0.010801 0.015919 -0.088156"/>
      <mass value="6.133134"/>
      <inertia ixx="0.123582" ixy="-0.001076" ixz="-0.007036" iyy="0.126866" iyz="0.008649" izz="0.011662"/>
    </inertial>
  </link>
  <joint name="leg_l4_joint" type="revolute">
    <!--   <origin rpy="0 0 0" xyz="0 0 -0.400"/>    -->
    <origin rpy="0 0 0" xyz="0 0 -0.400"/>
    <parent link="leg_l3_link"/>
    <child link="leg_l4_link"/>
    <axis xyz="0 -1 0"/>
    <dynamics damping="0" friction="0"/>
    <limit effort="200" lower="-2.4958208303518914" upper="-0.0" velocity="45"/>
  </joint>
  <link name="leg_l4_link">
    <visual>
      <origin rpy="0 0 0" xyz="0 0 0"/>
      <geometry>
        <mesh filename="package://h1_description/meshes/stl/leg_l4_link.STL" scale="1 1 1"/>
      </geometry>
      <material name="brown"/>
    </visual>
    <collision>
      <origin rpy="0 1.5707963267948966 0" xyz="0 0 -0.20"/>
      <geometry>
        <box size="0.45 0.05 0.05"/>
      </geometry>
    </collision>
    <inertial>
      <origin rpy="0 0 0" xyz="0.01358 0.005401 -0.18676"/>
      <mass value="2.757724"/>
      <inertia ixx="0.052429" ixy="-0.000618" ixz="0.002695" iyy="0.053962" iyz="-0.002004" izz="0.003135"/>
    </inertial>
  </link>
  <joint name="leg_l5_joint" type="revolute">
    <origin rpy="0 0 0" xyz="0 0 -0.4"/>
    <parent link="leg_l4_link"/>
    <child link="leg_l5_link"/>
    <axis xyz="0 1 0"/>
    <dynamics damping="0" friction="0"/>
    <limit effort="48" lower="-1.4835298641951802" upper="1.2042771838760873" velocity="40"/>
  </joint>
  <link name="leg_l5_link">
    <visual>
      <!--      <origin rpy="0 0 0" xyz="${leg_l5_link_length/2.0} 0 0"/>  -->
      <origin rpy="0 0 0" xyz="0 0 0"/>
      <geometry>
        <mesh filename="package://h1_description/meshes/stl/leg_l5_link.STL" scale="1 1 1"/>
      </geometry>
      <material name="brown"/>
    </visual>
    <collision>
      <!-- <origin rpy="0 0 0" xyz="0 0 0"/> -->
      <origin rpy="0 0 0" xyz="0.05 0 -0.04"/>
      <geometry>
        <box size="0.2 0.053 0.01"/>
      </geometry>
    </collision>
    <inertial>
      <origin rpy="0 0 0" xyz="0.033343 0.0 -0.028227"/>
      <mass value="0.325911"/>
      <inertia ixx="0.000104" ixy="0.0" ixz="-0.000115" iyy="0.001122" iyz="0.0" izz="0.001104"/>
    </inertial>
  </link>
  <joint name="leg_l5_fixed_1" type="fixed">
    <origin rpy="0 0 0" xyz="0.12 0 -0.04"/>
    <parent link="leg_l5_link"/>
    <child link="leg_l_f1_link"/>
  </joint>
  <link name="leg_l_f1_link">
    <inertial>
      <mass value="0.01"/>
      <inertia ixx="0.000001" ixy="0" ixz="0" iyy="0.000001" iyz="0" izz="0.000001"/>
    </inertial>
    <visual>
      <origin rpy="0 0 0" xyz="0 0 0"/>
      <geometry>
        <sphere radius="0.001"/>
      </geometry>
    </visual>
    <collision>
      <origin rpy="0 0 0" xyz="0 0 0"/>
      <geometry>
        <sphere radius="0.001"/>
      </geometry>
    </collision>
  </link>
  <joint name="leg_l5_fixed_2" type="fixed">
    <origin rpy="0 0 0" xyz="-0.01 0 -0.04"/>
    <parent link="leg_l5_link"/>
    <child link="leg_l_f2_link"/>
  </joint>
  <link name="leg_l_f2_link">
    <inertial>
      <mass value="0.01"/>
      <inertia ixx="0.000001" ixy="0" ixz="0" iyy="0.000001" iyz="0" izz="0.000001"/>
    </inertial>
    <visual>
      <origin rpy="0 0 0" xyz="0 0 0"/>
      <geometry>
        <sphere radius="0.001"/>
      </geometry>
    </visual>
    <collision>
      <origin rpy="0 0 0" xyz="-0 0 0"/>
      <geometry>
        <sphere radius="0.001"/>
      </geometry>
    </collision>
  </link>
  <transmission name="leg_l1_tran">
    <type>transmission_interface/SimpleTransmission</type>
    <joint name="leg_l1_joint">
      <hardwareInterface>hardware_interface/EffortJointInterface</hardwareInterface>
    </joint>
    <actuator name="leg_l1_motor">
      <hardwareInterface>hardware_interface/EffortJointInterface</hardwareInterface>
      <mechanicalReduction>1</mechanicalReduction>
      <maxVelocity>2.6545</maxVelocity>
      <!-- 85rpm -->
      <maxEffort>144.0</maxEffort>
      <!-- 36Nm -->
    </actuator>
  </transmission>
  <transmission name="leg_l2_tran">
    <type>transmission_interface/SimpleTransmission</type>
    <joint name="leg_l2_joint">
      <hardwareInterface>hardware_interface/EffortJointInterface</hardwareInterface>
    </joint>
    <actuator name="leg_l2_motor">
      <hardwareInterface>hardware_interface/EffortJointInterface</hardwareInterface>
      <mechanicalReduction>1</mechanicalReduction>
      <maxVelocity>2.6545</maxVelocity>
      <!-- 160rpm -->
      <maxEffort>144.0</maxEffort>
      <!-- 94Nm -->
    </actuator>
  </transmission>
  <transmission name="leg_l3_tran">
    <type>transmission_interface/SimpleTransmission</type>
    <joint name="leg_l3_joint">
      <hardwareInterface>hardware_interface/EffortJointInterface</hardwareInterface>
    </joint>
    <actuator name="leg_l3_motor">
      <hardwareInterface>hardware_interface/EffortJointInterface</hardwareInterface>
      <mechanicalReduction>1</mechanicalReduction>
      <maxVelocity>2.6545</maxVelocity>
      <!-- 160rpm -->
      <maxEffort>200.0</maxEffort>
      <!-- 94Nm -->
    </actuator>
  </transmission>
  <transmission name="leg_l4_tran">
    <type>transmission_interface/SimpleTransmission</type>
    <joint name="leg_l4_joint">
      <hardwareInterface>hardware_interface/EffortJointInterface</hardwareInterface>
    </joint>
    <actuator name="leg_l4_motor">
      <hardwareInterface>hardware_interface/EffortJointInterface</hardwareInterface>
      <mechanicalReduction>1</mechanicalReduction>
      <maxVelocity>2.6545</maxVelocity>
      <!-- 85rpm -->
      <maxEffort>200.0</maxEffort>
      <!-- 36Nm -->
    </actuator>
  </transmission>
  <transmission name="leg_l5_tran">
    <type>transmission_interface/SimpleTransmission</type>
    <joint name="leg_l5_joint">
      <hardwareInterface>hardware_interface/EffortJointInterface</hardwareInterface>
    </joint>
    <actuator name="leg_l5_motor">
      <hardwareInterface>hardware_interface/EffortJointInterface</hardwareInterface>
      <mechanicalReduction>1</mechanicalReduction>
      <maxVelocity>2.6545</maxVelocity>
      <!-- 85rpm -->
      <maxEffort>48.0</maxEffort>
      <!-- 36Nm -->
    </actuator>
  </transmission>
  <transmission name="leg_r1_tran">
    <type>transmission_interface/SimpleTransmission</type>
    <joint name="leg_r1_joint">
      <hardwareInterface>hardware_interface/EffortJointInterface</hardwareInterface>
    </joint>
    <actuator name="leg_r1_motor">
      <hardwareInterface>hardware_interface/EffortJointInterface</hardwareInterface>
      <mechanicalReduction>1</mechanicalReduction>
      <maxVelocity>2.6545</maxVelocity>
      <!-- 85rpm -->
      <maxEffort>144.0</maxEffort>
      <!-- 36Nm -->
    </actuator>
  </transmission>
  <transmission name="leg_r2_tran">
    <type>transmission_interface/SimpleTransmission</type>
    <joint name="leg_r2_joint">
      <hardwareInterface>hardware_interface/EffortJointInterface</hardwareInterface>
    </joint>
    <actuator name="leg_r2_motor">
      <hardwareInterface>hardware_interface/EffortJointInterface</hardwareInterface>
      <mechanicalReduction>1</mechanicalReduction>
      <maxVelocity>2.6545</maxVelocity>
      <!-- 160rpm -->
      <maxEffort>144.0</maxEffort>
      <!-- 94Nm -->
    </actuator>
  </transmission>
  <transmission name="leg_r3_tran">
    <type>transmission_interface/SimpleTransmission</type>
    <joint name="leg_r3_joint">
      <hardwareInterface>hardware_interface/EffortJointInterface</hardwareInterface>
    </joint>
    <actuator name="leg_r3_motor">
      <hardwareInterface>hardware_interface/EffortJointInterface</hardwareInterface>
      <mechanicalReduction>1</mechanicalReduction>
      <maxVelocity>2.6545</maxVelocity>
      <!-- 160rpm -->
      <maxEffort>200.0</maxEffort>
      <!-- 94Nm -->
    </actuator>
  </transmission>
  <transmission name="leg_r4_tran">
    <type>transmission_interface/SimpleTransmission</type>
    <joint name="leg_r4_joint">
      <hardwareInterface>hardware_interface/EffortJointInterface</hardwareInterface>
    </joint>
    <actuator name="leg_r4_motor">
      <hardwareInterface>hardware_interface/EffortJointInterface</hardwareInterface>
      <mechanicalReduction>1</mechanicalReduction>
      <maxVelocity>2.6545</maxVelocity>
      <!-- 85rpm -->
      <maxEffort>200.0</maxEffort>
      <!-- 36Nm -->
    </actuator>
  </transmission>
  <transmission name="leg_r5_tran">
    <type>transmission_interface/SimpleTransmission</type>
    <joint name="leg_r5_joint">
      <hardwareInterface>hardware_interface/EffortJointInterface</hardwareInterface>
    </joint>
    <actuator name="leg_r5_motor">
      <hardwareInterface>hardware_interface/EffortJointInterface</hardwareInterface>
      <mechanicalReduction>1</mechanicalReduction>
      <maxVelocity>2.6545</maxVelocity>
      <!-- 85rpm -->
      <maxEffort>48.0</maxEffort>
      <!-- 36Nm -->
    </actuator>
  </transmission>
</robot>

