<?xml version="1.0" ?>
<!-- =================================================================================== -->
<!-- |    This document was autogenerated by xacro from robot.xacro                    | -->
<!-- |    EDITING THIS FILE BY HAND IS NOT RECOMMENDED                                 | -->
<!-- =================================================================================== -->
<robot name="robot_description">
  <!--   <xacro:include filename="$(find h1_description)/xacro/transmission.xacro"/>   -->
  <!--   <xacro:include filename="$(find h1_description)/xacro/transmission.xacro"/>   -->
  <!--  <xacro:include filename="$(find human_robot_description)/xacro/transmission.xacro"/>  -->
  <material name="black">
    <color rgba="0.0 0.0 0.0 1.0"/>
  </material>
  <material name="blue">
    <color rgba="0.15 0.31 0.45 1.0"/>
  </material>
  <material name="green">
    <color rgba="0.0 0.8 0.0 1.0"/>
  </material>
  <material name="grey">
    <color rgba="0.2 0.2 0.2 1.0"/>
  </material>
  <material name="silver">
    <color rgba="0.9137254901960784 0.9137254901960784 0.8470588235294118 1.0"/>
  </material>
  <material name="orange">
    <color rgba="1.0 0.4235294117647059 0.0392156862745098 1.0"/>
  </material>
  <material name="brown">
    <color rgba="0.96 0.87 0.81 1.0"/>
  </material>
  <material name="red">
    <color rgba="0.8 0.0 0.0 1.0"/>
  </material>
  <material name="white">
    <color rgba="1.0 1.0 1.0 1.0"/>
  </material>
  <!--   <xacro:include filename="$(find human_robot_description)/xacro/gazebo.xacro"/>     -->
  <!--   <xacro:include filename="$(find human_robot_description)/xacro/imu.xacro"/>         -->
  <!--    <link name="base">-->
  <!--        <visual>-->
  <!--            <origin rpy="0 0 0" xyz="0 0 0"/>-->
  <!--            <geometry>-->
  <!--                <box size="0.001 0.001 0.001"/>-->
  <!--            </geometry>-->
  <!--        </visual>-->
  <!--    </link>-->
  <!--    <joint name="floating_base" type="fixed">-->
  <!--        <origin rpy="0 0 0" xyz="0 0 0"/>-->
  <!--        <parent link="base"/>-->
  <!--        <child link="trunk"/>-->
  <!--    </joint>-->
  <link name="trunk">
    <visual>
      <origin rpy="0 0 0" xyz="0 0 0"/>
      <geometry>
        <mesh filename="../meshes/dae/trunk.dae" scale="1 1 1"/>
      </geometry>
      <material name="blue"/>
    </visual>
    <collision>
      <origin rpy="0 0 0" xyz="0 0 0.033833333333333326"/>
      <geometry>
        <box size="0.15866666666666665 0.26 0.3353333333333333"/>
      </geometry>
    </collision>
    <inertial>
      <origin rpy="0 0 0" xyz="-0.030348 -6e-06 0.009963"/>
      <mass value="13.0"/>
      <inertia ixx="0.488866" ixy="1.5e-05" ixz="0.044913" iyy="0.432056" iyz="-1.1e-05" izz="0.217885"/>
    </inertial>
  </link>
  <joint name="head_joint" type="fixed">
    <origin rpy="0 0 0" xyz="0 0 0.38"/>
    <parent link="trunk"/>
    <child link="head"/>
  </joint>
  <link name="head">
    <visual>
      <origin rpy="0 0 0" xyz="0 0 0"/>
      <geometry>
        <mesh filename="../meshes/dae/head.dae" scale="1 1 1"/>
      </geometry>
      <material name="blue"/>
    </visual>
  </link>
  <joint name="arm_r1_joint" type="fixed">
    <origin rpy="0 0 0" xyz="0.02 -0.255 0.170"/>
    <parent link="trunk"/>
    <child link="arm_r1_link"/>
    <axis xyz="0 1 0"/>
    <dynamics damping="0" friction="0"/>
    <limit effort="24" lower="-3.141592653589793" upper="1.5707963267948966" velocity="40"/>
  </joint>
  <link name="arm_r1_link">
    <visual>
      <origin rpy="0 0 0" xyz="0 0 0"/>
      <geometry>
        <mesh filename="../meshes/dae/arm_r1_link.dae" scale="1 1 1"/>
      </geometry>
      <material name="brown"/>
    </visual>
    <collision>
      <origin rpy="0 1.5707963267948966 0" xyz="0 0 0"/>
      <geometry>
        <cylinder length="0.04" radius="0.0405"/>
      </geometry>
    </collision>
    <inertial>
      <origin rpy="0 0 0" xyz="-0.00111 -0.003638 -0.000101"/>
      <mass value="0.59"/>
      <inertia ixx="0.00065" ixy="-7e-06" ixz="0.0" iyy="0.000371" iyz="2e-06" izz="0.00044"/>
    </inertial>
  </link>
  <joint name="arm_r2_joint" type="fixed">
    <origin rpy="0 0 0" xyz="0 0 0"/>
    <parent link="arm_r1_link"/>
    <child link="arm_r2_link"/>
    <axis xyz="1 0 0"/>
    <dynamics damping="0" friction="0"/>
    <limit effort="24" lower="-2.897246558310587" upper="0.0" velocity="40"/>
  </joint>
  <link name="arm_r2_link">
    <visual>
      <origin rpy="0 0 0" xyz="0 0 0"/>
      <geometry>
        <mesh filename="../meshes/dae/arm_r2_link.dae" scale="1 1 1"/>
      </geometry>
      <material name="brown"/>
    </visual>
    <collision>
      <origin rpy="0 1.5707963267948966 0" xyz="0 0 -0.155"/>
      <geometry>
        <box size="0.22 0.0472 0.032"/>
      </geometry>
    </collision>
    <inertial>
      <origin rpy="0 0 0" xyz="0.0104 -0.002629 -0.175731"/>
      <mass value="0.69"/>
      <inertia ixx="0.009892" ixy="-8e-06" ixz="-0.000771" iyy="0.010106" iyz="0.000121" izz="0.000476"/>
    </inertial>
  </link>
  <joint name="arm_r3_joint" type="fixed">
    <!--    <origin rpy="0 0 0" xyz="0 0 ${-arm_r2_link_length}"/>   -->
    <!--   <origin rpy="0 0 0" xyz="0.04 -0.007 -0.2958"/>   -->
    <origin rpy="0 0 0" xyz="0.022 -0.007 -0.30"/>
    <parent link="arm_r2_link"/>
    <child link="arm_r3_link"/>
    <axis xyz="0 1 0"/>
    <dynamics damping="0" friction="0"/>
    <limit effort="12" lower="-2.8797932657906435" upper="0.6981317007977318" velocity="30"/>
  </joint>
  <link name="arm_r3_link">
    <visual>
      <origin rpy="0 0 0" xyz="0 0 0"/>
      <geometry>
        <mesh filename="../meshes/dae/arm_r3_link.dae" scale="1 1 1"/>
      </geometry>
      <material name="brown"/>
    </visual>
    <collision>
      <origin rpy="0 1.5707963267948966 0" xyz="0 0 -0.15"/>
      <geometry>
        <box size="0.24 0.042 0.054"/>
      </geometry>
    </collision>
    <inertial>
      <origin rpy="0 0 0" xyz="-0.018634 0.000258 -0.206007"/>
      <mass value="0.335672"/>
      <inertia ixx="0.003067" ixy="0.0" ixz="9.2e-05" iyy="0.003055" iyz="1.5e-05" izz="0.000228"/>
    </inertial>
  </link>
  <joint name="arm_l1_joint" type="fixed">
    <origin rpy="0 0 0" xyz="0.02 0.255 0.170"/>
    <parent link="trunk"/>
    <child link="arm_l1_link"/>
    <axis xyz="0 1 0"/>
    <dynamics damping="0" friction="0"/>
    <limit effort="24" lower="-3.141592653589793" upper="1.5707963267948966" velocity="40"/>
  </joint>
  <link name="arm_l1_link">
    <visual>
      <origin rpy="0 0 0" xyz="0 0 0"/>
      <geometry>
        <mesh filename="../meshes/dae/arm_l1_link.dae" scale="1 1 1"/>
      </geometry>
      <material name="brown"/>
    </visual>
    <collision>
      <!--   <origin rpy="${pi/2.0} 0 0" xyz="0 0 0"/>   -->
      <origin rpy="0 1.5707963267948966 0" xyz="0 0 0"/>
      <geometry>
        <cylinder length="0.04" radius="0.0405"/>
      </geometry>
    </collision>
    <inertial>
      <origin rpy="0 0 0" xyz="-0.00111 -0.003638 -0.000101"/>
      <mass value="0.59"/>
      <inertia ixx="0.00065" ixy="-7e-06" ixz="0.0" iyy="0.000371" iyz="2e-06" izz="0.00044"/>
    </inertial>
  </link>
  <joint name="arm_l2_joint" type="fixed">
    <origin rpy="0 0 0" xyz="0 0 0"/>
    <parent link="arm_l1_link"/>
    <child link="arm_l2_link"/>
    <axis xyz="1 0 0"/>
    <dynamics damping="0" friction="0"/>
    <limit effort="24" lower="0.0" upper="2.897246558310587" velocity="40"/>
  </joint>
  <link name="arm_l2_link">
    <visual>
      <origin rpy="0 0 0" xyz="0 0 0"/>
      <geometry>
        <mesh filename="../meshes/dae/arm_l2_link.dae" scale="1 1 1"/>
      </geometry>
      <material name="brown"/>
    </visual>
    <collision>
      <origin rpy="0 1.5707963267948966 0" xyz="0 0 -0.155"/>
      <geometry>
        <box size="0.22 0.0472 0.032"/>
      </geometry>
    </collision>
    <inertial>
      <origin rpy="0 0 0" xyz="0.0104 -0.002629 -0.175731"/>
      <mass value="0.69"/>
      <inertia ixx="0.009892" ixy="-8e-06" ixz="-0.000771" iyy="0.010106" iyz="5.3e-05" izz="0.000476"/>
    </inertial>
  </link>
  <joint name="arm_l3_joint" type="fixed">
    <!--   <origin rpy="0 0 0" xyz="0 0 ${-arm_l2_link_length}"/>    -->
    <!--    <origin rpy="0 0 0" xyz="0.04 -0.007 -0.2958"/>  -->
    <origin rpy="0 0 0" xyz="0.022 -0.007 -0.30"/>
    <parent link="arm_l2_link"/>
    <child link="arm_l3_link"/>
    <axis xyz="0 1 0"/>
    <dynamics damping="0" friction="0"/>
    <limit effort="12" lower="-2.8797932657906435" upper="0.6981317007977318" velocity="30"/>
  </joint>
  <link name="arm_l3_link">
    <visual>
      <origin rpy="0 0 0" xyz="0 0 0"/>
      <geometry>
        <mesh filename="../meshes/dae/arm_l3_link.dae" scale="1 1 1"/>
      </geometry>
      <material name="brown"/>
    </visual>
    <collision>
      <origin rpy="0 1.5707963267948966 0" xyz="0 0 -0.15"/>
      <geometry>
        <box size="0.24 0.042 0.054"/>
      </geometry>
    </collision>
    <inertial>
      <origin rpy="0 0 0" xyz="-0.018634 0.000258 -0.206007"/>
      <mass value="0.335672"/>
      <inertia ixx="0.003067" ixy="0.0" ixz="9.2e-05" iyy="0.003055" iyz="1.5e-05" izz="0.000228"/>
    </inertial>
  </link>
  <joint name="right_leg_roll_joint" type="revolute">
    <!--      <origin rpy="0 ${-pi/4.0} 0" xyz="-0.104 -0.081 -0.281"-0.02 0.080 -0.202/>  -->
    <origin rpy="0 0 0" xyz="0.02 -0.080 -0.202"/>
    <parent link="trunk"/>
    <child link="right_leg_roll_link"/>
    <axis xyz="1 0 0"/>
    <dynamics damping="0" friction="0"/>
    <limit effort="144" lower="-0.20943951023931953" upper="0.4886921905584123" velocity="45"/>
  </joint>
  <link name="right_leg_roll_link">
    <visual>
      <origin rpy="0 0 0" xyz="0 0 0"/>
      <geometry>
        <mesh filename="../meshes/dae/right_leg_roll_link.dae" scale="1 1 1"/>
      </geometry>
      <material name="brown"/>
    </visual>
    <collision>
      <origin rpy="0 0 0" xyz="0 0 0"/>
      <geometry>
        <cylinder length="0.05" radius="0.0558"/>
      </geometry>
    </collision>
    <inertial>
      <origin rpy="0 0 0" xyz="-0.04749 -0.00179 0.03144"/>
      <mass value="1.678032"/>
      <inertia ixx="0.001014" ixy="-1.039e-05" ixz="-2.165e-05" iyy="0.001329" iyz="-8.6e-06" izz="0.001662"/>
    </inertial>
  </link>
  <joint name="right_leg_yaw_joint" type="revolute">
    <!--      <origin rpy="0 0 0" xyz="0.148 -0.005 -0.01"/>   -->
    <origin rpy="0 0 0" xyz="0 -0.006 -0.13"/>
    <parent link="right_leg_roll_link"/>
    <child link="right_leg_yaw_link"/>
    <axis xyz="0 0 1"/>
    <dynamics damping="0" friction="0"/>
    <limit effort="144" lower="-0.20943951023931953" upper="0.5235987755982988" velocity="45"/>
  </joint>
  <link name="right_leg_yaw_link">
    <visual>
      <origin rpy="0 0 0" xyz="0 0 0"/>
      <geometry>
        <mesh filename="../meshes/dae/right_leg_yaw_link.dae" scale="1 1 1"/>
      </geometry>
      <material name="brown"/>
    </visual>
    <collision>
      <origin rpy="1.5707963267948966 0 0" xyz="0.01 0 0"/>
      <geometry>
        <cylinder length="0.052" radius="0.087"/>
      </geometry>
    </collision>
    <inertial>
      <origin rpy="0 0 0" xyz="-0.001279 -2.3e-05 0.007946"/>
      <mass value="2.697089"/>
      <inertia ixx="0.007298" ixy="-4e-06" ixz="-0.000181" iyy="0.012498" iyz="8.2e-05" izz="0.006774"/>
    </inertial>
  </link>
  <joint name="right_leg_pitch_joint" type="revolute">
    <!--     <origin rpy="0 0 0" xyz="0 -0.057 0"/>   -->
    <origin rpy="0 0 0" xyz="0 -0.057 0"/>
    <parent link="right_leg_yaw_link"/>
    <child link="right_leg_pitch_link"/>
    <axis xyz="0 -1 0"/>
    <dynamics damping="0" friction="0"/>
    <limit effort="200" lower="-1.1344640137963142" upper="1.335176877775662" velocity="45"/>
  </joint>
  <link name="right_leg_pitch_link">
    <visual>
      <origin rpy="0 0 0" xyz="0 0 0"/>
      <geometry>
        <mesh filename="../meshes/dae/right_leg_pitch_link.dae" scale="1 1 1"/>
      </geometry>
      <material name="brown"/>
    </visual>
    <collision>
      <origin rpy="0 1.5707963267948966 0" xyz="0.03 0 -0.200"/>
      <geometry>
        <box size="0.3 0.05 0.05"/>
      </geometry>
    </collision>
    <inertial>
      <origin rpy="0 0 0" xyz="0.009533 0.015634 -0.086474"/>
      <mass value="6.102984"/>
      <inertia ixx="0.122149" ixy="-0.000936" ixz="-0.005516" iyy="0.125073" iyz="0.008296" izz="0.011251"/>
    </inertial>
  </link>
  <joint name="right_knee_joint" type="revolute">
    <!--   <origin rpy="0 0 0" xyz="0 0 -0.400"/>  -->
    <origin rpy="0 0 0" xyz="0 0 -0.400"/>
    <parent link="right_leg_pitch_link"/>
    <child link="right_knee_link"/>
    <axis xyz="0 -1 0"/>
    <dynamics damping="0" friction="0"/>
    <limit effort="200" lower="-2.4958208303518914" upper="-0.175" velocity="45"/>
  </joint>
  <link name="right_knee_link">
    <visual>
      <origin rpy="0 0 0" xyz="0 0 0"/>
      <geometry>
        <mesh filename="../meshes/dae/right_knee_link.dae" scale="1 1 1"/>
      </geometry>
      <material name="brown"/>
    </visual>
    <collision>
      <origin rpy="0 1.5707963267948966 0" xyz="0 0 -0.15"/>
      <geometry>
        <box size="0.3 0.05 0.05"/>
      </geometry>
    </collision>
    <inertial>
      <origin rpy="0 0 0" xyz="0.014051 0.005019 -0.177311"/>
      <mass value="2.691601"/>
      <inertia ixx="0.04675" ixy="-0.000639" ixz="0.00188" iyy="0.04831" iyz="-0.001706" izz="0.003109"/>
    </inertial>
  </link>
  <joint name="right_ankle_pitch_joint" type="revolute">
    <origin rpy="0 0 0" xyz="0 0 -0.4"/>
    <parent link="right_knee_link"/>
    <child link="right_ankle_pitch_link"/>
    <axis xyz="0 1 0"/>
    <dynamics damping="0" friction="0"/>
    <limit effort="48" lower="-1.4835298641951802" upper="1.2042771838760873" velocity="40"/>
  </joint>
  <link name="right_ankle_pitch_link">
    <visual>
      <!--    <origin rpy="0 0 0" xyz="${rightfoot_length/2.0} 0 0"/>  -->
      <origin rpy="0 0 0" xyz="0 0 0"/>
      <geometry>
        <mesh filename="../meshes/dae/right_ankle_pitch_link.dae" scale="1 1 1"/>
      </geometry>
      <material name="brown"/>
    </visual>
    <collision>
      <origin rpy="0 0 0" xyz="0.05 0 -0.04"/>
      <geometry>
        <box size="0.2 0.053 0.01"/>
      </geometry>
    </collision>
    <inertial>
      <origin rpy="0 0 0" xyz="0.017698 -0.003063 -0.021891"/>
      <mass value="0.450099"/>
      <inertia ixx="0.000198" ixy="7.2e-05" ixz="-0.000225" iyy="0.0015" iyz="-2e-05" izz="0.00147"/>
    </inertial>
  </link>
  <joint name="left_leg_roll_joint" type="revolute">
    <origin rpy="0 0 0" xyz="0.02 0.080 -0.202"/>
    <parent link="trunk"/>
    <child link="left_leg_roll_link"/>
    <axis xyz="1 0 0"/>
    <dynamics damping="0" friction="0"/>
    <limit effort="144" lower="-0.20943951023931953" upper="0.4886921905584123" velocity="45"/>
  </joint>
  <link name="left_leg_roll_link">
    <visual>
      <origin rpy="0 0 0" xyz="0 0 0"/>
      <geometry>
        <mesh filename="../meshes/dae/left_leg_roll_link.dae" scale="1 1 1"/>
      </geometry>
      <material name="brown"/>
    </visual>
    <collision>
      <origin rpy="0 0 0" xyz="0 0 0"/>
      <geometry>
        <cylinder length="0.05" radius="0.0558"/>
      </geometry>
    </collision>
    <inertial>
      <origin rpy="0 0 0" xyz="-0.04749 -0.00179 0.03144"/>
      <mass value="1.678032"/>
      <inertia ixx="0.001014" ixy="-1.039e-05" ixz="-2.165e-05" iyy="0.001329" iyz="-8.6e-06" izz="0.001662"/>
    </inertial>
  </link>
  <joint name="left_leg_yaw_joint" type="revolute">
    <!--   <origin rpy="0 0 0" xyz="0.103 0 -0.103"/>0 -0.006 -0.13  -->
    <origin rpy="0 0 0" xyz="0 -0.006 -0.13"/>
    <parent link="left_leg_roll_link"/>
    <child link="left_leg_yaw_link"/>
    <axis xyz="0 0 1"/>
    <dynamics damping="0" friction="0"/>
    <limit effort="144" lower="-0.20943951023931953" upper="0.5235987755982988" velocity="45"/>
  </joint>
  <link name="left_leg_yaw_link">
    <visual>
      <origin rpy="0 0 0" xyz="0 0 0"/>
      <geometry>
        <mesh filename="../meshes/dae/left_leg_yaw_link.dae" scale="1 1 1"/>
      </geometry>
      <material name="brown"/>
    </visual>
    <collision>
      <!-- <origin rpy="${pi/2} 0 0" xyz="${left_leg_yaw_link_radius} 0 0"/>       -->
      <origin rpy="1.5707963267948966 0 0" xyz="0 0 0"/>
      <geometry>
        <cylinder length="0.052" radius="0.087"/>
      </geometry>
    </collision>
    <inertial>
      <origin rpy="0 0 0" xyz="-0.001279 -2.3e-05 0.007946"/>
      <mass value="2.697089"/>
      <inertia ixx="0.007298" ixy="-4e-06" ixz="-0.000181" iyy="0.012498" iyz="8.2e-05" izz="0.006774"/>
    </inertial>
  </link>
  <joint name="left_leg_pitch_joint" type="revolute">
    <!--   <origin rpy="0 0 0" xyz="0 0.057 0"/> -->
    <origin rpy="0 0 0" xyz="0 0.057 0"/>
    <parent link="left_leg_yaw_link"/>
    <child link="left_leg_pitch_link"/>
    <axis xyz="0 -1 0"/>
    <dynamics damping="0" friction="0"/>
    <limit effort="200" lower="-1.1344640137963142" upper="1.335176877775662" velocity="45"/>
  </joint>
  <link name="left_leg_pitch_link">
    <visual>
      <origin rpy="0 0 0" xyz="0 0 0"/>
      <geometry>
        <mesh filename="../meshes/dae/left_leg_pitch_link.dae" scale="1 1 1"/>
      </geometry>
      <material name="brown"/>
    </visual>
    <collision>
      <origin rpy="0 1.5707963267948966 0" xyz="0.03 0 -0.200"/>
      <geometry>
        <box size="0.3 0.05 0.05"/>
      </geometry>
    </collision>
    <inertial>
      <origin rpy="0 0 0" xyz="0.009533 0.015634 -0.086474"/>
      <mass value="6.102984"/>
      <inertia ixx="0.122149" ixy="-0.000936" ixz="-0.005516" iyy="0.125073" iyz="0.008296" izz="0.011251"/>
    </inertial>
  </link>
  <joint name="left_knee_joint" type="revolute">
    <!--   <origin rpy="0 0 0" xyz="0 0 -0.400"/>    -->
    <origin rpy="0 0 0" xyz="0 0 -0.400"/>
    <parent link="left_leg_pitch_link"/>
    <child link="left_knee_link"/>
    <axis xyz="0 -1 0"/>
    <dynamics damping="0" friction="0"/>
    <limit effort="200" lower="-2.4958208303518914" upper="-0.175" velocity="45"/>
  </joint>
  <link name="left_knee_link">
    <visual>
      <origin rpy="0 0 0" xyz="0 0 0"/>
      <geometry>
        <mesh filename="../meshes/dae/left_knee_link.dae" scale="1 1 1"/>
      </geometry>
      <material name="brown"/>
    </visual>
    <collision>
      <origin rpy="0 1.5707963267948966 0" xyz="0 0 -0.15"/>
      <geometry>
        <box size="0.3 0.05 0.05"/>
      </geometry>
    </collision>
    <inertial>
      <origin rpy="0 0 0" xyz="0.014051 0.005019 -0.177311"/>
      <mass value="2.691601"/>
      <inertia ixx="0.04675" ixy="-0.000639" ixz="0.00188" iyy="0.04831" iyz="-0.001706" izz="0.003109"/>
    </inertial>
  </link>
  <joint name="left_ankle_pitch_joint" type="revolute">
    <origin rpy="0 0 0" xyz="0 0 -0.4"/>
    <parent link="left_knee_link"/>
    <child link="left_ankle_pitch_link"/>
    <axis xyz="0 1 0"/>
    <dynamics damping="0" friction="0"/>
    <limit effort="48" lower="-1.4835298641951802" upper="1.2042771838760873" velocity="40"/>
  </joint>
  <link name="left_ankle_pitch_link">
    <visual>
      <!--      <origin rpy="0 0 0" xyz="${left_ankle_pitch_link_length/2.0} 0 0"/>  -->
      <origin rpy="0 0 0" xyz="0 0 0"/>
      <geometry>
        <mesh filename="../meshes/dae/left_ankle_pitch_link.dae" scale="1 1 1"/>
      </geometry>
      <material name="brown"/>
    </visual>
    <collision>
      <!-- <origin rpy="0 0 0" xyz="0 0 0"/> -->
      <origin rpy="0 0 0" xyz="0.05 0 -0.04"/>
      <geometry>
        <box size="0.2 0.053 0.01"/>
      </geometry>
    </collision>
    <inertial>
      <origin rpy="0 0 0" xyz="0.015501 0.002509 -0.019173"/>
      <mass value="0.513908"/>
      <inertia ixx="0.000241" ixy="-6.7e-05" ixz="-0.000247" iyy="0.001548" iyz="1.4e-05" izz="0.001503"/>
    </inertial>
  </link>
</robot>

